Traceback (most recent call last):
  File "/Users/kat/Library/Caches/pypoetry/virtualenvs/hello-julia-zBHhK2FC-py3.13/lib/python3.13/site-packages/jupyter_core/utils/__init__.py", line 154, in wrapped
    asyncio.get_running_loop()
    ~~~~~~~~~~~~~~~~~~~~~~~~^^
RuntimeError: no running event loop

During handling of the above exception, another exception occurred:

Traceback (most recent call last):
  File "/Users/kat/Library/Caches/pypoetry/virtualenvs/hello-julia-zBHhK2FC-py3.13/lib/python3.13/site-packages/jupyter_cache/executors/utils.py", line 58, in single_nb_execution
    executenb(
    ~~~~~~~~~^
        nb,
        ^^^
    ...<4 lines>...
        **kwargs,
        ^^^^^^^^^
    )
    ^
  File "/Users/kat/Library/Caches/pypoetry/virtualenvs/hello-julia-zBHhK2FC-py3.13/lib/python3.13/site-packages/nbclient/client.py", line 1319, in execute
    return NotebookClient(nb=nb, resources=resources, km=km, **kwargs).execute()
           ~~~~~~~~~~~~~~~~~~~~~~~~~~~~~~~~~~~~~~~~~~~~~~~~~~~~~~~~~~~~~~~~~~~^^
  File "/Users/kat/Library/Caches/pypoetry/virtualenvs/hello-julia-zBHhK2FC-py3.13/lib/python3.13/site-packages/jupyter_core/utils/__init__.py", line 158, in wrapped
    return loop.run_until_complete(inner)
           ~~~~~~~~~~~~~~~~~~~~~~~^^^^^^^
  File "/opt/homebrew/Cellar/python@3.13/3.13.2/Frameworks/Python.framework/Versions/3.13/lib/python3.13/asyncio/base_events.py", line 725, in run_until_complete
    return future.result()
           ~~~~~~~~~~~~~^^
  File "/Users/kat/Library/Caches/pypoetry/virtualenvs/hello-julia-zBHhK2FC-py3.13/lib/python3.13/site-packages/nbclient/client.py", line 709, in async_execute
    await self.async_execute_cell(
        cell, index, execution_count=self.code_cells_executed + 1
    )
  File "/Users/kat/Library/Caches/pypoetry/virtualenvs/hello-julia-zBHhK2FC-py3.13/lib/python3.13/site-packages/nbclient/client.py", line 1062, in async_execute_cell
    await self._check_raise_for_error(cell, cell_index, exec_reply)
  File "/Users/kat/Library/Caches/pypoetry/virtualenvs/hello-julia-zBHhK2FC-py3.13/lib/python3.13/site-packages/nbclient/client.py", line 918, in _check_raise_for_error
    raise CellExecutionError.from_cell_and_msg(cell, exec_reply_content)
nbclient.exceptions.CellExecutionError: An error occurred while executing the following cell:
------------------
option.type = "put"
------------------


setfield!: immutable struct of type NamedTuple cannot be changed

Stacktrace:
 [1] [0m[1msetproperty![22m[0m[1m([22m[90mx[39m::[0m@NamedTuple[90m{type::String, strike::Int64, expiry::String}[39m, [90mf[39m::[0mSymbol, [90mv[39m::[0mString[0m[1m)[22m
[90m   @[39m [90mBase[39m [90m./[39m[90m[4mBase.jl:53[24m[39m
 [2] top-level scope
[90m   @[39m [90m[4mIn[6]:1[24m[39m

